<?xml version="1.0" encoding="utf-8"?>
<!-- This URDF was automatically created by SolidWorks to URDF Exporter! Originally created by Stephen Brawner (brawner@gmail.com) 
     Commit Version: 1.6.0-4-g7f85cfe  Build Version: 1.6.7995.38578
     For more information, please see http://wiki.ros.org/sw_urdf_exporter -->
<robot
  name="Base_con_ruedas_para_ROS_URDF.SLDASM">
  <link
    name="base_link">
    <inertial>
      <origin
        xyz="-0.11878744502835 -0.00950436788509916 0.0821383092403481"
        rpy="0 0 0" />
      <mass
        value="2.83771948238293" />
      <inertia
        ixx="0.0430332674788693"
        ixy="1.40958244923047E-10"
        ixz="2.13042531567236E-07"
        iyy="0.0430332674788692"
        iyz="2.13042531609337E-07"
        izz="0.0857213097167914" />
    </inertial>
    <visual>
      <origin
        xyz="0 0 0"
        rpy="0 0 0" />
      <geometry>
        <mesh
          filename="package://Base_con_ruedas_para_ROS_URDF.SLDASM/meshes/base_link.STL" />
      </geometry>
      <material
        name="">
        <color
          rgba="0.792156862745098 0.819607843137255 0.933333333333333 1" />
      </material>
    </visual>
    <collision>
      <origin
        xyz="0 0 0"
        rpy="0 0 0" />
      <geometry>
        <mesh
          filename="package://Base_con_ruedas_para_ROS_URDF.SLDASM/meshes/base_link.STL" />
      </geometry>
    </collision>
  </link>
  <link
    name="w1">
    <inertial>
      <origin
        xyz="-1.7538E-06 1.7536E-06 0.0010792"
        rpy="0 0 0" />
      <mass
        value="0.037695" />
      <inertia
        ixx="3.0971E-06"
        ixy="-1.1843E-11"
        ixz="-6.2069E-10"
        iyy="3.0971E-06"
        iyz="6.2066E-10"
        izz="5.3487E-06" />
    </inertial>
    <visual>
      <origin
        xyz="0 0 0"
        rpy="0 0 0" />
      <geometry>
        <mesh
          filename="package://Base_con_ruedas_para_ROS_URDF.SLDASM/meshes/w1.STL" />
      </geometry>
      <material
        name="">
        <color
          rgba="0.75294 0.75294 0.75294 1" />
      </material>
    </visual>
    <collision>
      <origin
        xyz="0 0 0"
        rpy="0 0 0" />
      <geometry>
        <mesh
          filename="package://Base_con_ruedas_para_ROS_URDF.SLDASM/meshes/w1.STL" />
      </geometry>
    </collision>
  </link>
  <joint
    name="joint_wheel1"
    type="continuous">
    <origin
      xyz="0.083096 -0.071358 -0.2114"
      rpy="2.5572 -0.559 0.89496" />
    <parent
      link="base_link" />
    <child
      link="w1" />
    <axis
      xyz="0 0 1" />
  </joint>
  <link
    name="w2">
    <inertial>
      <origin
        xyz="-1.75375275950074E-06 1.75360376633571E-06 0.0571792446888183"
        rpy="0 0 0" />
      <mass
        value="0.0376949548905805" />
      <inertia
        ixx="3.09710701266864E-06"
        ixy="4.90406058546246E-11"
        ixz="-6.20695592251457E-10"
        iyy="3.09717632566126E-06"
        iyz="6.20655769719843E-10"
        izz="5.3487591588829E-06" />
    </inertial>
    <visual>
      <origin
        xyz="0 0 0"
        rpy="0 0 0" />
      <geometry>
        <mesh
          filename="package://Base_con_ruedas_para_ROS_URDF.SLDASM/meshes/w2.STL" />
      </geometry>
      <material
        name="">
        <color
          rgba="0.752941176470588 0.752941176470588 0.752941176470588 1" />
      </material>
    </visual>
    <collision>
      <origin
        xyz="0 0 0"
        rpy="0 0 0" />
      <geometry>
        <mesh
          filename="package://Base_con_ruedas_para_ROS_URDF.SLDASM/meshes/w2.STL" />
      </geometry>
    </collision>
  </link>
  <joint
    name="joint_wheel2"
    type="continuous">
    <origin
      xyz="0.043427 -0.07138 0.15271"
      rpy="0.42925 0.67987 0.6293" />
    <parent
      link="base_link" />
    <child
      link="w2" />
    <axis
      xyz="0 0 1" />
  </joint>
  <link
    name="w3">
    <inertial>
      <origin
        xyz="-1.75375554717361E-06 1.75360628151822E-06 0.0010791779906677"
        rpy="0 0 0" />
      <mass
        value="0.0376949548647" />
      <inertia
        ixx="3.09718950231943E-06"
        ixy="-5.10087033948385E-11"
        ixz="-6.20695595482421E-10"
        iyy="3.09717846728405E-06"
        iyz="6.20659344083231E-10"
        izz="5.34884380066944E-06" />
    </inertial>
    <visual>
      <origin
        xyz="0 0 0"
        rpy="0 0 0" />
      <geometry>
        <mesh
          filename="package://Base_con_ruedas_para_ROS_URDF.SLDASM/meshes/w3.STL" />
      </geometry>
      <material
        name="">
        <color
          rgba="0.752941176470588 0.752941176470588 0.752941176470588 1" />
      </material>
    </visual>
    <collision>
      <origin
        xyz="0 0 0"
        rpy="0 0 0" />
      <geometry>
        <mesh
          filename="package://Base_con_ruedas_para_ROS_URDF.SLDASM/meshes/w3.STL" />
      </geometry>
    </collision>
  </link>
  <joint
    name="joint_wheel3"
    type="continuous">
    <origin
      xyz="-0.32068 -0.071358 0.19238"
      rpy="0 -0.7854 0" />
    <parent
      link="base_link" />
    <child
      link="w3" />
    <axis
      xyz="0 0 1" />
  </joint>
  <link
    name="w4">
    <inertial>
      <origin
        xyz="-1.75375391844868E-06 1.75360373740052E-06 0.0458838619195954"
        rpy="0 0 0" />
      <mass
        value="0.0376949548786197" />
      <inertia
        ixx="3.09721164599084E-06"
        ixy="-1.48517341651876E-11"
        ixz="-6.20693853218012E-10"
        iyy="3.0972556715952E-06"
        iyz="6.20658421022023E-10"
        izz="5.34894314268096E-06" />
    </inertial>
    <visual>
      <origin
        xyz="0 0 0"
        rpy="0 0 0" />
      <geometry>
        <mesh
          filename="package://Base_con_ruedas_para_ROS_URDF.SLDASM/meshes/w4.STL" />
      </geometry>
      <material
        name="">
        <color
          rgba="0.752941176470588 0.752941176470588 0.752941176470588 1" />
      </material>
    </visual>
    <collision>
      <origin
        xyz="0 0 0"
        rpy="0 0 0" />
      <geometry>
        <mesh
          filename="package://Base_con_ruedas_para_ROS_URDF.SLDASM/meshes/w4.STL" />
      </geometry>
    </collision>
  </link>
  <joint
    name="joint_wheel3"
    type="continuous">
    <origin
      xyz="-0.289 -0.071358 -0.17972"
      rpy="-2.3563 0.013593 1.5572" />
    <parent
      link="base_link" />
    <child
      link="w4" />
    <axis
      xyz="0 0 1" />
  </joint>
</robot>